Workbook

Sheet Page 1
A1: GRAEBEL INTERNATIONAL VALUED INVENTORY
A3: Please check the appropriate shipment type
A5: TRANSFEREE | D5: Origin City, Country | J5: Date Packed
A7: Destination (Complete Address)
A9: Instructions: Declare the Replacement Cost at destination of all items in your shipment below or submit your own legible listing of items and their Replacement Cost.
A10: Items not declared and valued are not eligible for protection. Items of dissimilar value should be separately declared.
A11: Articles | B11: No. Items | C11: Destination Replace. Cost | D11: Articles | E11: No. Items | F11: Destination Replace. Cost | G11: Articles | H11: No. Items | I11: Destination Replace. Cost | J11: Articles | K11: No. Items | L11: Destination Replace. Cost
A12: A. LIVING ROOM | D12: G. KITCHEN | G12: J. BEDROOM NO. 1 (Master) | J12: N. CLOTHING/LINENS
A13: Bookcase/Room Divider | D13: Table/Chairs | G13: Bed(s) | J13: Suits
A14: Sofa | D14: Cabinets | G14: Mattress(es) | J14: Coats/Jackets
A15: Love Seat | D15: Dishes | G15: Night Table(s) | J15: Dresses
A16: Chair(s)/Ottoman(s) | D16: Bowls, Trays, Etc. | G16: Lamp(s) | J16: Sport Coats
A17: Cushions/Pillows | D17: Glassware | G17: Dressing Table/Vanity | J17: Slacks
A18: Lamp(s) | D18: Utensils/Cutlery | G18: Chair(s) | J18: Sweaters
A19: Coffee/Center Table | D19: Pots & Pans | G19: Chest of Drawers | J19: Blouses
A20: Other Table(s) | D20: Linens & Curtains | G20: Armoire/Wardrobe | J20: Skirts
A21: Rug(s)/Carpet(s) | D21: Step Stool | G21: Bookcase(s) | J21: Shirts
A22: Curtains/Drapes | D22: Trash/Garbage Cans | G22: Desk/Chair | J22: Sleepwear
A23: Mirror(s) | D23: Microwave | G23: Mirror(s) | J23: Shoes/Boots
... A25: Sofa Covers | D25: Refrigerator/Freezer | G25: Rug(s)/Carpet(s) | J25: Hosiery/Socks
D26: Dishwasher | G26: Other (Please specify) | J26: Ties/Scarves
A27: Sub-Total | C27: =SUM(C13:C26) -> 0 | D27: Electrical Appliances | G27: Sub-Total | I27: =SUM(I13:I26) -> 0 | J27: Underwear
A28: B. DINING ROOM | D28: Liquor/Wine | G28: K. BEDROOM NO. 2 | J28: Lingerie
A29: Table | D29: Other (Please specify) | G29: Bed(s) | J29: Sportswear
A30: Chair(s) | G30: Mattress(es) | J30: Hats
A31: China Closet | G31: Night Table(s)
A32: Buffet | G32: Lamp(s)
A33: Serving Table/Tea Cart | D33: Sub-Total | F33: =SUM(F13:F32) -> 0 | G33: Dressing Table/Vanity | J33: Pillows
A34: Lamp(s)/Chandelier(s) | G34: Chair(s) | J34: Sheets/Pillow Cases
A35: Rug(s)/Carpet(s) | G35: Chest of Drawers | J35: Blankets
A36: Curtains/Drapes | D36: H. OFFICE | G36: Armoire/Wardrobe | J36: Comforters/Duvets
A37: Mirror(s) | D37: Desk/Chair | G37: Bookcase(s) | J37: Quilts
A38: Table Linen/Accessories | D38: Lamp(s) | G38: Desk/Chair | J38: Drying Rack
A39: Other (Please specify) | D39: Filing Cabinet(s) | G39: Mirror(s) | J39: Iron/Ironing Board
D40: Bookcase(s) | G40: Curtains/Drapes | J40: Other (Please specify)
D41: Telephone | G41: Rug(s)/Carpet(s)
A42: Sub-Total | C42: =SUM(C29:C41) -> 0 | D42: Answering Machine | G42: Other (Please specify)
A43: C. CHINA | D43: FAX Machine | G43: Sub-Total | I43: =SUM(I29:I42) -> 0
D44: Typewriter(s) | G44: L. BEDROOM NO. 3
D45: Copier | G45: Bed(s) | J45: Sub-Total | L45: =SUM(L13:L44) -> 0
...

Sheet Page 2
A1: GRAEBEL INTERNATIONAL VALUED INVENTORY
A3: Articles | B3: No. Items | C3: Destination Replace. Cost | D3: AUTOMOBILES/MOTORCYCLES/BOATS | G3: CALCULATION COLUMN
A4: P. MISCELLANEOUS | D4: R. ITEM 1 | G4: HOUSEHOLD GOODS
A5: Statues/Figurines | D5: (Circle One) Automobile Motorcycle Boat | G5: A. Living Room | I5: ='Page 1'!C27 -> 0
A6: Decorative Objects | G6: B. Dining Room | I6: ='Page 1'!C42 -> 0
A7: Piano | D7: Yr./Make: | G7: C. China | I7: ='Page 1'!C47 -> 0
A8: Other Musical Instruments | D8: Serial No.: | G8: D. Crystal | I8: ='Page 1'!C52 -> 0
A9: Clock(s) | D9: Value: | G9: E. Silver | I9: ='Page 1'!C57 -> 0
A10: Baskets/Plant Holders | G10: F. Den/Family Room | I10: ='Page 1'!C71 -> 0
A11: Artificial Plants | G11: G. Kitchen | I11: ='Page 1'!F33 -> 0
A12: Pictures/Paintings | D12: S. ITEM 2 | G12: H. Office | I12: ='Page 1'!F53 -> 0
A13: Books | D13: (Circle One) Automobile Motorcycle Boat | G13: I. Basement & Garage | I13: ='Page 1'!F71 -> 0
A14: Video Tapes - DVD | G14: J. Bedroom No. 1 (master) | I14: ='Page 1'!I27 -> 0
A15: CDs/Tapes/Records | D15: Yr./Make: | G15: K. Bedroom No. 2 | I15: ='Page 1'!I43 -> 0
A16: Toys/Games | D16: Serial No.: | G16: L. Bedroom No. 3 | I16: ='Page 1'!I59 -> 0
A17: Bicycles | D17: Value: | G17: M. Bathrooms | I17: ='Page 1'!I71 -> 0
A18: Exercise Equipment | G18: N. Clothing/Linens | I18: ='Page 1'!L45 -> 0
A19: Sports Equipment | G19: O. Electronics | I19: ='Page 1'!L71 -> 0
A20: Camping Equipment | D20: T. ACCESSORIES FOR ITEMS 1 & 2 | G20: P. Miscellaneous | I20: =C29 -> 0
A21: Fireplace Equipement | D21: Non-factory installed accessories must be separately listed and valued: | G21: Q. Unusual Nature or Value | I21: =D39 -> 0
A22: Sewing Machine | G22: TOTAL | I22: =SUM(I5:I21) -> 0
A23: Sewing Supplies
A24: Craft Supplies
A25: Holiday Decorations | G25: AUTOMOBILES/MOTORCYCLES/BOATS
A26: Other (Please specify) | G26: R. Item 1 | I26: =E9 -> 0
G27: S. Item 2 | I27: =E17 -> 0
G28: T. Accessories | I28: =F29 -> 0
A29: Sub-Total | C29: =SUM(C5:C28) -> 0 | D29: Sub-Total | F29: =SUM(F22:F28) -> 0 | G29: TOTAL | I29: =SUM(I26:I28) -> 0
A31: Q. ITEMS OF UNUSUAL NATURE OR VALUE
A32: Item | C32: No. Items | D32: Destination Replace. Cost | E32: Comments
A39: Sub-Total | D39: =SUM(D33:D38) -> 0
F41: VALUED AMOUNT
F42: HOUSEHOLD GOODS | H42: =I22 -> 0
F43: AUTOMOBILES/MOTORCYCLES/BOATS | H43: =I29 -> 0
F44: GRAND TOTAL US$ | H44: =SUM(H42:I43) -> 0
A47: Transferee's Signature: | D47: Date
A49: Please sign and return with the Election of Protection form to your Graebel Customer Service Coordinator.
